ERROR:root:Except on auto_unfollow!
Traceback (most recent call last):
  File "C:\Users\Aji Reza\Documents\bot\src\instabot.py", line 867, in auto_unfollow
    all_data = json.loads(re.search('{"activity.+show_app', r.text, re.DOTALL).group(0)+'":""}')['entry_data']['ProfilePage'][0]
AttributeError: 'NoneType' object has no attribute 'group'
ERROR:root:Except on auto_unfollow!
Traceback (most recent call last):
  File "C:\Users\Aji Reza\Documents\bot\src\instabot.py", line 867, in auto_unfollow
    all_data = json.loads(re.search('{"activity.+show_app', r.text, re.DOTALL).group(0)+'":""}')['entry_data']['ProfilePage'][0]
AttributeError: 'NoneType' object has no attribute 'group'
ERROR:root:Except on auto_unfollow!
Traceback (most recent call last):
  File "C:\Users\Aji Reza\Documents\bot\src\instabot.py", line 867, in auto_unfollow
    all_data = json.loads(re.search('{"activity.+show_app', r.text, re.DOTALL).group(0)+'":""}')['entry_data']['ProfilePage'][0]
AttributeError: 'NoneType' object has no attribute 'group'
ERROR:root:Except on unfollow... Looks like a network error
Traceback (most recent call last):
  File "C:\Users\Aji Reza\AppData\Local\Programs\Python\Python36\lib\site-packages\urllib3\connectionpool.py", line 377, in _make_request
    httplib_response = conn.getresponse(buffering=True)
TypeError: getresponse() got an unexpected keyword argument 'buffering'

During handling of the above exception, another exception occurred:

Traceback (most recent call last):
  File "C:\Users\Aji Reza\Documents\bot\src\instabot.py", line 664, in unfollow_on_cleanup
    unfollow = self.s.post(url_unfollow)
  File "C:\Users\Aji Reza\AppData\Local\Programs\Python\Python36\lib\site-packages\requests\sessions.py", line 559, in post
    return self.request('POST', url, data=data, json=json, **kwargs)
  File "C:\Users\Aji Reza\AppData\Local\Programs\Python\Python36\lib\site-packages\requests\sessions.py", line 512, in request
    resp = self.send(prep, **send_kwargs)
  File "C:\Users\Aji Reza\AppData\Local\Programs\Python\Python36\lib\site-packages\requests\sessions.py", line 622, in send
    r = adapter.send(request, **kwargs)
  File "C:\Users\Aji Reza\AppData\Local\Programs\Python\Python36\lib\site-packages\requests\adapters.py", line 445, in send
    timeout=timeout
  File "C:\Users\Aji Reza\AppData\Local\Programs\Python\Python36\lib\site-packages\urllib3\connectionpool.py", line 600, in urlopen
    chunked=chunked)
  File "C:\Users\Aji Reza\AppData\Local\Programs\Python\Python36\lib\site-packages\urllib3\connectionpool.py", line 380, in _make_request
    httplib_response = conn.getresponse()
  File "C:\Users\Aji Reza\AppData\Local\Programs\Python\Python36\lib\http\client.py", line 1331, in getresponse
    response.begin()
  File "C:\Users\Aji Reza\AppData\Local\Programs\Python\Python36\lib\http\client.py", line 297, in begin
    version, status, reason = self._read_status()
  File "C:\Users\Aji Reza\AppData\Local\Programs\Python\Python36\lib\http\client.py", line 258, in _read_status
    line = str(self.fp.readline(_MAXLINE + 1), "iso-8859-1")
  File "C:\Users\Aji Reza\AppData\Local\Programs\Python\Python36\lib\socket.py", line 586, in readinto
    return self._sock.recv_into(b)
  File "C:\Users\Aji Reza\AppData\Local\Programs\Python\Python36\lib\ssl.py", line 1009, in recv_into
    return self.read(nbytes, buffer)
  File "C:\Users\Aji Reza\AppData\Local\Programs\Python\Python36\lib\ssl.py", line 871, in read
    return self._sslobj.read(len, buffer)
  File "C:\Users\Aji Reza\AppData\Local\Programs\Python\Python36\lib\ssl.py", line 631, in read
    v = self._sslobj.read(len, buffer)
KeyboardInterrupt
